Workbook
Name Slicer_Product_Type: #N/A
Name Slicer_Shipping_carriers: #N/A
Name Slicer_Stock_Risk: #N/A
Name Slicer_Supplier_name: #N/A
Name Slicer_Supplier_Performance_Flag: #N/A

Sheet Raw_dataset
A1: Product type | B1: SKU | C1: Price | D1: Availability | E1: Number of products sold | F1: Revenue generated | G1: Customer demographics | H1: Stock levels | I1: Lead times | J1: Order quantities | K1: Shipping times | L1: Shipping carriers | M1: Shipping costs | N1: Supplier name | O1: Location | P1: Lead time | Q1: Production volumes | R1: Manufacturing lead time | S1: Manufacturing costs | T1: Inspection results | U1: Defect rates | V1: Transportation modes | W1: Routes | X1: Costs
A2: haircare | B2: SKU0 | C2: 69.808006 | D2: 55 | E2: 802 | F2: 8661.9968 | G2: Non-binary | H2: 58 | I2: 7 | J2: 96 | K2: 4 | L2: Carrier B | M2: 2.9565721 | N2: Supplier 3 | O2: Mumbai | P2: 29 | Q2: 215 | R2: 29 | S2: 46.279879 | T2: Pending | U2: 0.22641036 | V2: Road | W2: Route B | X2: 187.75208
A3: skincare | B3: SKU1 | C3: 14.843523 | D3: 95 | E3: 736 | F3: 7460.9001 | G3: Female | H3: 53 | I3: 30 | J3: 37 | K3: 2 | L3: Carrier A | M3: 9.7165748 | N3: Supplier 3 | O3: Mumbai | P3: 23 | Q3: 517 | R3: 30 | S3: 33.616769 | T3: Pending | U3: 4.854068 | V3: Road | W3: Route B | X3: 503.06558
A4: haircare | B4: SKU2 | C4: 11.319683 | D4: 34 | E4: 8 | F4: 9577.7496 | G4: Unknown | H4: 1 | I4: 10 | J4: 88 | K4: 2 | L4: Carrier B | M4: 8.0544793 | N4: Supplier 1 | O4: Mumbai | P4: 12 | Q4: 971 | R4: 27 | S4: 30.688019 | T4: Pending | U4: 4.5805926 | V4: Air | W4: Route C | X4: 141.92028
A5: skincare | B5: SKU3 | C5: 61.163343 | D5: 68 | E5: 83 | F5: 7766.8364 | G5: Non-binary | H5: 23 | I5: 13 | J5: 59 | K5: 6 | L5: Carrier C | M5: 1.7295686 | N5: Supplier 5 | O5: Kolkata | P5: 24 | Q5: 937 | R5: 18 | S5: 35.624741 | T5: Fail | U5: 4.7466486 | V5: Rail | W5: Route A | X5: 254.77616
A6: skincare | B6: SKU4 | C6: 4.805496 | D6: 26 | E6: 871 | F6: 2686.5052 | G6: Non-binary | H6: 5 | I6: 3 | J6: 56 | K6: 8 | L6: Carrier A | M6: 3.8905479 | N6: Supplier 1 | O6: Delhi | P6: 5 | Q6: 414 | R6: 3 | S6: 92.065161 | T6: Fail | U6: 3.1455795 | V6: Air | W6: Route A | X6: 923.44063
A7: haircare | B7: SKU5 | C7: 1.699976 | D7: 87 | E7: 147 | F7: 2828.3487 | G7: Non-binary | H7: 90 | I7: 27 | J7: 66 | K7: 3 | L7: Carrier B | M7: 4.4440989 | N7: Supplier 4 | O7: Bangalore | P7: 10 | Q7: 104 | R7: 17 | S7: 56.766476 | T7: Fail | U7: 2.7791935 | V7: Road | W7: Route A | X7: 235.46124
A8: skincare | B8: SKU6 | C8: 4.0783329 | D8: 48 | E8: 65 | F8: 7823.4766 | G8: Male | H8: 11 | I8: 15 | J8: 58 | K8: 8 | L8: Carrier C | M8: 3.8807633 | N8: Supplier 3 | O8: Kolkata | P8: 14 | Q8: 314 | R8: 24 | S8: 1.0850686 | T8: Pending | U8: 1.0009106 | V8: Sea | W8: Route A | X8: 134.3691
A9: cosmetics | B9: SKU7 | C9: 42.958384 | D9: 59 | E9: 426 | F9: 8496.1038 | G9: Female | H9: 93 | I9: 17 | J9: 11 | K9: 1 | L9: Carrier B | M9: 2.3483388 | N9: Supplier 4 | O9: Bangalore | P9: 22 | Q9: 564 | R9: 1 | S9: 99.466109 | T9: Fail | U9: 0.39817719 | V9: Road | W9: Route C | X9: 802.05631
A10: cosmetics | B10: SKU8 | C10: 68.717597 | D10: 78 | E10: 150 | F10: 7517.3632 | G10: Female | H10: 5 | I10: 10 | J10: 15 | K10: 7 | L10: Carrier C | M10: 3.4047339 | N10: Supplier 4 | O10: Mumbai | P10: 13 | Q10: 769 | R10: 8 | S10: 11.423027 | T10: Pending | U10: 2.7098627 | V10: Sea | W10: Route B | X10: 505.55713
A11: skincare | B11: SKU9 | C11: 64.015733 | D11: 35 | E11: 980 | F11: 4971.146 | G11: Unknown | H11: 14 | I11: 27 | J11: 83 | K11: 1 | L11: Carrier A | M11: 7.1666453 | N11: Supplier 2 | O11: Chennai | P11: 29 | Q11: 963 | R11: 23 | S11: 47.957602 | T11: Pending | U11: 3.8446145 | V11: Rail | W11: Route B | X11: 995.92946
A12: skincare | B12: SKU10 | C12: 15.707796 | D12: 11 | E12: 996 | F12: 2330.9658 | G12: Non-binary | H12: 51 | I12: 13 | J12: 80 | K12: 2 | L12: Carrier C | M12: 8.6732112 | N12: Supplier 5 | O12: Kolkata | P12: 18 | Q12: 830 | R12: 5 | S12: 96.527353 | T12: Pass | U12: 1.7273139 | V12: Road | W12: Route B | X12: 806.10318
A13: skincare | B13: SKU11 | C13: 90.63546 | D13: 95 | E13: 960 | F13: 6099.9441 | G13: Female | H13: 46 | I13: 23 | J13: 60 | K13: 1 | L13: Carrier A | M13: 4.5239431 | N13: Supplier 2 | O13: Kolkata | P13: 28 | Q13: 362 | R13: 11 | S13: 27.592363 | T13: Pending | U13: 0.021169821 | V13: Air | W13: Route A | X13: 126.72303
... A101: haircare | B101: SKU99 | C101: 68.517833 | D101: 17 | E101: 627 | F101: 9185.1858 | G101: Unknown | H101: 55 | I101: 8 | J101: 59 | K101: 6 | L101: Carrier B | M101: 1.3110238 | N101: Supplier 2 | O101: Chennai | P101: 29 | Q101: 921 | R101: 2 | S101: 38.072899 | T101: Fail | U101: 0.34602729 | V101: Rail | W101: Route B | X101: 210.74301

Sheet clean_data
A1: Product Type | B1: SKU | C1: Price | D1: Availability | E1: Number of products sold | F1: Revenue generated | G1: Customer demographics | H1: Stock levels | I1: order Lead times | J1: Order quantities | K1: Shipping times | L1: Shipping carriers | M1: Shipping costs | N1: Supplier name | O1: Location | P1: Lead time | Q1: Production volumes | R1: Manufacturing lead time | S1: Manufacturing costs | T1: Inspection results | U1: Defect rates | V1: Transportation modes | W1: Routes | X1: Costs | Y1: Profit | Z1: profit margin % | AA1: Stock Risk | AB1: Revenue Tier | AC1: Defect Category | AD1: Total Lead Time | AE1: Shipping Cost Per Unit | AF1: Supplier Performance Flag
A2: Haircare | B2: SKU42 | C2: 46.529168 | D2: 98 | E2: 155 | F2: 1839.6094 | G2: Female | H2: 22 | I2: 27 | J2: 57 | K2: 4 | L2: Carrier C | M2: 7.5262483 | N2: Supplier 5 | O2: Bangalore | P2: 26 | Q2: 179 | R2: 7 | S2: 96.422821 | T2: Fail | U2: 0.049392553 | V2: Road | W2: Route A | X2: 635.65712 | Y2: =F2 -X2 -> 1203.9523 | Z2: =(Table3[[#This Row],[Revenue generated]]-Table3[[#This Row],[Costs]])/Table3[[#This Row],[Revenue generated]] -> 0.65446083 | AA2: =IF(Table3[[#This Row],[Stock levels]]<Table3[[#This Row],[Order quantities]]*0.2,"Critical",IF(Table3[[#This Row],[Stock levels]]<Table3[[#This Row],[Order quantities]]*0.5,"low","Adquate")) -> low | AB2: =IF( F2 >=Calculations!$B$3,"High", IF(F2 >=Calculations!$B$2,"Medium", "Low")) -> Low | AC2: =_xlfn.IFS(Table3[[#This Row],[Defect rates]] < 0.02,"Excellent",Table3[[#This Row],[Defect rates]] < 0.05,"Acceptable",Table3[[#This Row],[Defect rates]] < 0.1,"Concerning",Table3[[#This Row],[Defect rates]] > 0.1,"Critical") -> Acceptable | AD2: =Table3[[#This Row],[order Lead times]]+Table3[[#This Row],[Manufacturing lead time]] -> 34 | AE2: =Table3[[#This Row],[Shipping costs]]/Table3[[#This Row],[Number of products sold]] -> 0.048556441 | AF2: =IF(AND(Table3[[#This Row],[Total Lead Time]]>Calculations!$B$6, Table3[[#This Row],[Defect rates]]>Calculations!$B$7), "Underperforming", IF(Table3[[#This Row],[Total Lead Time]]>Calculations!$B$6, "Slow", IF(Table3[[#This Row],[Defect rates]]>Calculations!$B$7, "Quality Issue", "Good"))) -> Good
A3: Skincare | B3: SKU65 | C3: 33.697717 | D3: 72 | E3: 457 | F3: 8354.5797 | G3: Male | H3: 57 | I3: 24 | J3: 54 | K3: 8 | L3: Carrier C | M3: 6.5805413 | N3: Supplier 5 | O3: Kolkata | P3: 16 | Q3: 358 | R3: 21 | S3: 1.5972227 | T3: Fail | U3: 0.04911096 | V3: Rail | W3: Route C | X3: 555.8591 | Y3: =F3 -X3 -> 7798.7206 | Z3: =(Table3[[#This Row],[Revenue generated]]-Table3[[#This Row],[Costs]])/Table3[[#This Row],[Revenue generated]] -> 0.93346654 | AA3: =IF(Table3[[#This Row],[Stock levels]]<Table3[[#This Row],[Order quantities]]*0.2,"Critical",IF(Table3[[#This Row],[Stock levels]]<Table3[[#This Row],[Order quantities]]*0.5,"low","Adquate")) -> Adquate | AB3: =IF( F3 >=Calculations!$B$3,"High", IF(F3 >=Calculations!$B$2,"Medium", "Low")) -> High | AC3: =_xlfn.IFS(Table3[[#This Row],[Defect rates]] < 0.02,"Excellent",Table3[[#This Row],[Defect rates]] < 0.05,"Acceptable",Table3[[#This Row],[Defect rates]] < 0.1,"Concerning",Table3[[#This Row],[Defect rates]] > 0.1,"Critical") -> Acceptable | AD3: =Table3[[#This Row],[order Lead times]]+Table3[[#This Row],[Manufacturing lead time]] -> 45 | AE3: =Table3[[#This Row],[Shipping costs]]/Table3[[#This Row],[Number of products sold]] -> 0.014399434 | AF3: =IF(AND(Table3[[#This Row],[Total Lead Time]]>Calculations!$B$6, Table3[[#This Row],[Defect rates]]>Calculations!$B$7), "Underperforming", IF(Table3[[#This Row],[Total Lead Time]]>Calculations!$B$6, "Slow", IF(Table3[[#This Row],[Defect rates]]>Calculations!$B$7, "Quality Issue", "Good"))) -> Slow
A4: Haircare | B4: SKU1 | C4: 14.843523 | D4: 95 | E4: 736 | F4: 7460.9001 | G4: Female | H4: 53 | I4: 30 | J4: 37 | K4: 2 | L4: Carrier A | M4: 9.7165748 | N4: Supplier 3 | O4: Mumbai | P4: 23 | Q4: 517 | R4: 30 | S4: 33.616769 | T4: Pending | U4: 0.04854068 | V4: Road | W4: Route B | X4: 503.06558 | Y4: =F4 -X4 -> 6957.8345 | Z4: =(Table3[[#This Row],[Revenue generated]]-Table3[[#This Row],[Costs]])/Table3[[#This Row],[Revenue generated]] -> 0.93257307 | AA4: =IF(Table3[[#This Row],[Stock levels]]<Table3[[#This Row],[Order quantities]]*0.2,"Critical",IF(Table3[[#This Row],[Stock levels]]<Table3[[#This Row],[Order quantities]]*0.5,"low","Adquate")) -> Adquate | AB4: =IF( F4 >=Calculations!$B$3,"High", IF(F4 >=Calculations!$B$2,"Medium", "Low")) -> Medium | AC4: =_xlfn.IFS(Table3[[#This Row],[Defect rates]] < 0.02,"Excellent",Table3[[#This Row],[Defect rates]] < 0.05,"Acceptable",Table3[[#This Row],[Defect rates]] < 0.1,"Concerning",Table3[[#This Row],[Defect rates]] > 0.1,"Critical") -> Acceptable | AD4: =Table3[[#This Row],[order Lead times]]+Table3[[#This Row],[Manufacturing lead time]] -> 60 | AE4: =Table3[[#This Row],[Shipping costs]]/Table3[[#This Row],[Number of products sold]] -> 0.013201868 | AF4: =IF(AND(Table3[[#This Row],[Total Lead Time]]>Calculations!$B$6, Table3[[#This Row],[Defect rates]]>Calculations!$B$7), "Underperforming", IF(Table3[[#This Row],[Total Lead Time]]>Calculations!$B$6, "Slow", IF(Table3[[#This Row],[Defect rates]]>Calculations!$B$7, "Quality Issue", "Good"))) -> Slow
A5: Cosmetics | B5: SKU84 | C5: 89.104367 | D5: 99 | E5: 618 | F5: 2048.2901 | G5: Unknown | H5: 73 | I5: 26 | J5: 80 | K5: 10 | L5: Carrier A | M5: 8.3816156 | N5: Supplier 5 | O5: Chennai | P5: 24 | Q5: 589 | R5: 22 | S5: 33.808637 | T5: Pass | U5: 0.048434566 | V5: Air | W5: Route B | X5: 465.45701 | Y5: =F5 -X5 -> 1582.8331 | Z5: =(Table3[[#This Row],[Revenue generated]]-Table3[[#This Row],[Costs]])/Table3[[#This Row],[Revenue generated]] -> 0.77275826 | AA5: =IF(Table3[[#This Row],[Stock levels]]<Table3[[#This Row],[Order quantities]]*0.2,"Critical",IF(Table3[[#This Row],[Stock levels]]<Table3[[#This Row],[Order quantities]]*0.5,"low","Adquate")) -> Adquate | AB5: =IF( F5 >=Calculations!$B$3,"High", IF(F5 >=Calculations!$B$2,"Medium", "Low")) -> Low | AC5: =_xlfn.IFS(Table3[[#This Row],[Defect rates]] < 0.02,"Excellent",Table3[[#This Row],[Defect rates]] < 0.05,"Acceptable",Table3[[#This Row],[Defect rates]] < 0.1,"Concerning",Table3[[#This Row],[Defect rates]] > 0.1,"Critical") -> Acceptable | AD5: =Table3[[#This Row],[order Lead times]]+Table3[[#This Row],[Manufacturing lead time]] -> 48 | AE5: =Table3[[#This Row],[Shipping costs]]/Table3[[#This Row],[Number of products sold]] -> 0.013562485 | AF5: =IF(AND(Table3[[#This Row],[Total Lead Time]]>Calculations!$B$6, Table3[[#This Row],[Defect rates]]>Calculations!$B$7), "Underperforming", IF(Table3[[#This Row],[Total Lead Time]]>Calculations!$B$6, "Slow", IF(Table3[[#This Row],[Defect rates]]>Calculations!$B$7, "Quality Issue", "Good"))) -> Slow
A6: Haircare | B6: SKU50 | C6: 14.203484 | D6: 91 | E6: 633 | F6: 5910.8854 | G6: Female | H6: 31 | I6: 23 | J6: 82 | K6: 10 | L6: Carrier A | M6: 6.2478609 | N6: Supplier 2 | O6: Delhi | P6: 20 | Q6: 306 | R6: 21 | S6: 45.178758 | T6: Fail | U6: 0.047548008 | V6: Rail | W6: Route B | X6: 496.24865 | Y6: =F6 -X6 -> 5414.6367 | Z6: =(Table3[[#This Row],[Revenue generated]]-Table3[[#This Row],[Costs]])/Table3[[#This Row],[Revenue generated]] -> 0.91604495 | AA6: =IF(Table3[[#This Row],[Stock levels]]<Table3[[#This Row],[Order quantities]]*0.2,"Critical",IF(Table3[[#This Row],[Stock levels]]<Table3[[#This Row],[Order quantities]]*0.5,"low","Adquate")) -> low | AB6: =IF( F6 >=Calculations!$B$3,"High", IF(F6 >=Calculations!$B$2,"Medium", "Low")) -> Medium | AC6: =_xlfn.IFS(Table3[[#This Row],[Defect rates]] < 0.02,"Excellent",Table3[[#This Row],[Defect rates]] < 0.05,"Acceptable",Table3[[#This Row],[Defect rates]] < 0.1,"Concerning",Table3[[#This Row],[Defect rates]] > 0.1,"Critical") -> Acceptable | AD6: =Table3[[#This Row],[order Lead times]]+Table3[[#This Row],[Manufacturing lead time]] -> 44 | AE6: =Table3[[#This Row],[Shipping costs]]/Table3[[#This Row],[Number of products sold]] -> 0.0098702384 | AF6: =IF(AND(Table3[[#This Row],[Total Lead Time]]>Calculations!$B$6, Table3[[#This Row],[Defect rates]]>Calculations!$B$7), "Underperforming", IF(Table3[[#This Row],[Total Lead Time]]>Calculations!$B$6, "Slow", IF(Table3[[#This Row],[Defect rates]]>Calculations!$B$7, "Quality Issue", "Good"))) -> Slow
A7: Skincare | B7: SKU3 | C7: 61.163343 | D7: 68 | E7: 83 | F7: 7766.8364 | G7: Non-binary | H7: 23 | I7: 13 | J7: 59 | K7: 6 | L7: Carrier C | M7: 1.7295686 | N7: Supplier 5 | O7: Kolkata | P7: 24 | Q7: 937 | R7: 18 | S7: 35.624741 | T7: Fail | U7: 0.047466486 | V7: Rail | W7: Route A | X7: 254.77616 | Y7: =F7 -X7 -> 7512.0603 | Z7: =(Table3[[#This Row],[Revenue generated]]-Table3[[#This Row],[Costs]])/Table3[[#This Row],[Revenue generated]] -> 0.96719692 | AA7: =IF(Table3[[#This Row],[Stock levels]]<Table3[[#This Row],[Order quantities]]*0.2,"Critical",IF(Table3[[#This Row],[Stock levels]]<Table3[[#This Row],[Order quantities]]*0.5,"low","Adquate")) -> low | AB7: =IF( F7 >=Calculations!$B$3,"High", IF(F7 >=Calculations!$B$2,"Medium", "Low")) -> High | AC7: =_xlfn.IFS(Table3[[#This Row],[Defect rates]] < 0.02,"Excellent",Table3[[#This Row],[Defect rates]] < 0.05,"Acceptable",Table3[[#This Row],[Defect rates]] < 0.1,"Concerning",Table3[[#This Row],[Defect rates]] > 0.1,"Critical") -> Acceptable | AD7: =Table3[[#This Row],[order Lead times]]+Table3[[#This Row],[Manufacturing lead time]] -> 31 | AE7: =Table3[[#This Row],[Shipping costs]]/Table3[[#This Row],[Number of products sold]] -> 0.020838175 | AF7: =IF(AND(Table3[[#This Row],[Total Lead Time]]>Calculations!$B$6, Table3[[#This Row],[Defect rates]]>Calculations!$B$7), "Underperforming", IF(Table3[[#This Row],[Total Lead Time]]>Calculations!$B$6, "Slow", IF(Table3[[#This Row],[Defect rates]]>Calculations!$B$7, "Quality Issue", "Good"))) -> Good
A8: Haircare | B8: SKU73 | C8: 83.851018 | D8: 41 | E8: 375 | F8: 7910.8869 | G8: Male | H8: 17 | I8: 25 | J8: 66 | K8: 5 | L8: Carrier B | M8: 1.5129368 | N8: Supplier 4 | O8: Chennai | P8: 13 | Q8: 444 | R8: 4 | S8: 46.870239 | T8: Fail | U8: 0.046205461 | V8: Road | W8: Route A | X8: 866.4728 | Y8: =F8 -X8 -> 7044.4141 | Z8: =(Table3[[#This Row],[Revenue generated]]-Table3[[#This Row],[Costs]])/Table3[[#This Row],[Revenue generated]] -> 0.89047084 | AA8: =IF(Table3[[#This Row],[Stock levels]]<Table3[[#This Row],[Order quantities]]*0.2,"Critical",IF(Table3[[#This Row],[Stock levels]]<Table3[[#This Row],[Order quantities]]*0.5,"low","Adquate")) -> low | AB8: =IF( F8 >=Calculations!$B$3,"High", IF(F8 >=Calculations!$B$2,"Medium", "Low")) -> High | AC8: =_xlfn.IFS(Table3[[#This Row],[Defect rates]] < 0.02,"Excellent",Table3[[#This Row],[Defect rates]] < 0.05,"Acceptable",Table3[[#This Row],[Defect rates]] < 0.1,"Concerning",Table3[[#This Row],[Defect rates]] > 0.1,"Critical") -> Acceptable | AD8: =Table3[[#This Row],[order Lead times]]+Table3[[#This Row],[Manufacturing lead time]] -> 29 | AE8: =Table3[[#This Row],[Shipping costs]]/Table3[[#This Row],[Number of products sold]] -> 0.0040344982 | AF8: =IF(AND(Table3[[#This Row],[Total Lead Time]]>Calculations!$B$6, Table3[[#This Row],[Defect rates]]>Calculations!$B$7), "Underperforming", IF(Table3[[#This Row],[Total Lead Time]]>Calculations!$B$6, "Slow", IF(Table3[[#This Row],[Defect rates]]>Calculations!$B$7, "Quality Issue", "Good"))) -> Good
A9: Skincare | B9: SKU2 | C9: 11.319683 | D9: 34 | E9: 8 | F9: 9577.7496 | G9: Unknown | H9: 1 | I9: 10 | J9: 88 | K9: 2 | L9: Carrier B | M9: 8.0544793 | N9: Supplier 1 | O9: Mumbai | P9: 12 | Q9: 971 | R9: 27 | S9: 30.688019 | T9: Pending | U9: 0.045805926 | V9: Air | W9: Route C | X9: 141.92028 | Y9: =F9 -X9 -> 9435.8293 | Z9: =(Table3[[#This Row],[Revenue generated]]-Table3[[#This Row],[Costs]])/Table3[[#This Row],[Revenue generated]] -> 0.98518229 | AA9: =IF(Table3[[#This Row],[Stock levels]]<Table3[[#This Row],[Order quantities]]*0.2,"Critical",IF(Table3[[#This Row],[Stock levels]]<Table3[[#This Row],[Order quantities]]*0.5,"low","Adquate")) -> Critical | AB9: =IF( F9 >=Calculations!$B$3,"High", IF(F9 >=Calculations!$B$2,"Medium", "Low")) -> High | AC9: =_xlfn.IFS(Table3[[#This Row],[Defect rates]] < 0.02,"Excellent",Table3[[#This Row],[Defect rates]] < 0.05,"Acceptable",Table3[[#This Row],[Defect rates]] < 0.1,"Concerning",Table3[[#This Row],[Defect rates]] > 0.1,"Critical") -> Acceptable | AD9: =Table3[[#This Row],[order Lead times]]+Table3[[#This Row],[Manufacturing lead time]] -> 37 | AE9: =Table3[[#This Row],[Shipping costs]]/Table3[[#This Row],[Number of products sold]] -> 1.0068099 | AF9: =IF(AND(Table3[[#This Row],[Total Lead Time]]>Calculations!$B$6, Table3[[#This Row],[Defect rates]]>Calculations!$B$7), "Underperforming", IF(Table3[[#This Row],[Total Lead Time]]>Calculations!$B$6, "Slow", IF(Table3[[#This Row],[Defect rates]]>Calculations!$B$7, "Quality Issue", "Good"))) -> Good
A10: Skincare | B10: SKU55 | C10: 79.855058 | D10: 16 | E10: 701 | F10: 2925.6752 | G10: Male | H10: 97 | I10: 11 | J10: 11 | K10: 5 | L10: Carrier A | M10: 5.014365 | N10: Supplier 2 | O10: Delhi | P10: 27 | Q10: 918 | R10: 5 | S10: 30.323545 | T10: Fail | U10: 0.045489197 | V10: Sea | W10: Route B | X10: 323.01293 | Y10: =F10 -X10 -> 2602.6622 | Z10: =(Table3[[#This Row],[Revenue generated]]-Table3[[#This Row],[Costs]])/Table3[[#This Row],[Revenue generated]] -> 0.88959371 | AA10: =IF(Table3[[#This Row],[Stock levels]]<Table3[[#This Row],[Order quantities]]*0.2,"Critical",IF(Table3[[#This Row],[Stock levels]]<Table3[[#This Row],[Order quantities]]*0.5,"low","Adquate")) -> Adquate | AB10: =IF( F10 >=Calculations!$B$3,"High", IF(F10 >=Calculations!$B$2,"Medium", "Low")) -> Low | AC10: =_xlfn.IFS(Table3[[#This Row],[Defect rates]] < 0.02,"Excellent",Table3[[#This Row],[Defect rates]] < 0.05,"Acceptable",Table3[[#This Row],[Defect rates]] < 0.1,"Concerning",Table3[[#This Row],[Defect rates]] > 0.1,"Critical") -> Acceptable | AD10: =Table3[[#This Row],[order Lead times]]+Table3[[#This Row],[Manufacturing lead time]] -> 16 | AE10: =Table3[[#This Row],[Shipping costs]]/Table3[[#This Row],[Number of products sold]] -> 0.0071531597 | AF10: =IF(AND(Table3[[#This Row],[Total Lead Time]]>Calculations!$B$6, Table3[[#This Row],[Defect rates]]>Calculations!$B$7), "Underperforming", IF(Table3[[#This Row],[Total Lead Time]]>Calculations!$B$6, "Slow", IF(Table3[[#This Row],[Defect rates]]>Calculations!$B$7, "Quality Issue", "Good"))) -> Good
A11: Cosmetics | B11: SKU61 | C11: 52.02875 | D11: 23 | E11: 117 | F11: 6885.5894 | G11: Unknown | H11: 32 | I11: 23 | J11: 36 | K11: 7 | L11: Carrier C | M11: 9.0303404 | N11: Supplier 4 | O11: Kolkata | P11: 14 | Q11: 480 | R11: 12 | S11: 78.702394 | T11: Fail | U11: 0.043674705 | V11: Air | W11: Route A | X11: 164.36653 | Y11: =F11 -X11 -> 6721.2228 | Z11: =(Table3[[#This Row],[Revenue generated]]-Table3[[#This Row],[Costs]])/Table3[[#This Row],[Revenue generated]] -> 0.97612891 | AA11: =IF(Table3[[#This Row],[Stock levels]]<Table3[[#This Row],[Order quantities]]*0.2,"Critical",IF(Table3[[#This Row],[Stock levels]]<Table3[[#This Row],[Order quantities]]*0.5,"low","Adquate")) -> Adquate | AB11: =IF( F11 >=Calculations!$B$3,"High", IF(F11 >=Calculations!$B$2,"Medium", "Low")) -> Medium | AC11: =_xlfn.IFS(Table3[[#This Row],[Defect rates]] < 0.02,"Excellent",Table3[[#This Row],[Defect rates]] < 0.05,"Acceptable",Table3[[#This Row],[Defect rates]] < 0.1,"Concerning",Table3[[#This Row],[Defect rates]] > 0.1,"Critical") -> Acceptable | AD11: =Table3[[#This Row],[order Lead times]]+Table3[[#This Row],[Manufacturing lead time]] -> 35 | AE11: =Table3[[#This Row],[Shipping costs]]/Table3[[#This Row],[Number of products sold]] -> 0.077182397 | AF11: =IF(AND(Table3[[#This Row],[Total Lead Time]]>Calculations!$B$6, Table3[[#This Row],[Defect rates]]>Calculations!$B$7), "Underperforming", IF(Table3[[#This Row],[Total Lead Time]]>Calculations!$B$6, "Slow", IF(Table3[[#This Row],[Defect rates]]>Calculations!$B$7, "Quality Issue", "Good"))) -> Good
A12: Cosmetics | B12: SKU20 | C12: 96.341072 | D12: 22 | E12: 320 | F12: 8128.0277 | G12: Unknown | H12: 27 | I12: 12 | J12: 68 | K12: 6 | L12: Carrier A | M12: 8.8783347 | N12: Supplier 1 | O12: Chennai | P12: 29 | Q12: 309 | R12: 6 | S12: 65.68626 | T12: Pass | U12: 0.042314166 | V12: Air | W12: Route B | X12: 493.87122 | Y12: =F12 -X12 -> 7634.1565 | Z12: =(Table3[[#This Row],[Revenue generated]]-Table3[[#This Row],[Costs]])/Table3[[#This Row],[Revenue generated]] -> 0.93923849 | AA12: =IF(Table3[[#This Row],[Stock levels]]<Table3[[#This Row],[Order quantities]]*0.2,"Critical",IF(Table3[[#This Row],[Stock levels]]<Table3[[#This Row],[Order quantities]]*0.5,"low","Adquate")) -> low | AB12: =IF( F12 >=Calculations!$B$3,"High", IF(F12 >=Calculations!$B$2,"Medium", "Low")) -> High | AC12: =_xlfn.IFS(Table3[[#This Row],[Defect rates]] < 0.02,"Excellent",Table3[[#This Row],[Defect rates]] < 0.05,"Acceptable",Table3[[#This Row],[Defect rates]] < 0.1,"Concerning",Table3[[#This Row],[Defect rates]] > 0.1,"Critical") -> Acceptable | AD12: =Table3[[#This Row],[order Lead times]]+Table3[[#This Row],[Manufacturing lead time]] -> 18 | AE12: =Table3[[#This Row],[Shipping costs]]/Table3[[#This Row],[Number of products sold]] -> 0.027744796 | AF12: =IF(AND(Table3[[#This Row],[Total Lead Time]]>Calculations!$B$6, Table3[[#This Row],[Defect rates]]>Calculations!$B$7), "Underperforming", IF(Table3[[#This Row],[Total Lead Time]]>Calculations!$B$6, "Slow", IF(Table3[[#This Row],[Defect rates]]>Calculations!$B$7, "Quality Issue", "Good"))) -> Good
A13: Skincare | B13: SKU40 | C13: 80.541424 | D13: 97 | E13: 933 | F13: 5724.9594 | G13: Female | H13: 90 | I13: 20 | J13: 39 | K13: 8 | L13: Carrier C | M13: 7.2295951 | N13: Supplier 1 | O13: Kolkata | P13: 18 | Q13: 793 | R13: 1 | S13: 88.179407 | T13: Pending | U13: 0.042132694 | V13: Road | W13: Route A | X13: 529.80872 | Y13: =F13 -X13 -> 5195.1506 | Z13: =(Table3[[#This Row],[Revenue generated]]-Table3[[#This Row],[Costs]])/Table3[[#This Row],[Revenue generated]] -> 0.90745633 | AA13: =IF(Table3[[#This Row],[Stock levels]]<Table3[[#This Row],[Order quantities]]*0.2,"Critical",IF(Table3[[#This Row],[Stock levels]]<Table3[[#This Row],[Order quantities]]*0.5,"low","Adquate")) -> Adquate | AB13: =IF( F13 >=Calculations!$B$3,"High", IF(F13 >=Calculations!$B$2,"Medium", "Low")) -> Medium | AC13: =_xlfn.IFS(Table3[[#This Row],[Defect rates]] < 0.02,"Excellent",Table3[[#This Row],[Defect rates]] < 0.05,"Acceptable",Table3[[#This Row],[Defect rates]] < 0.1,"Concerning",Table3[[#This Row],[Defect rates]] > 0.1,"Critical") -> Acceptable | AD13: =Table3[[#This Row],[order Lead times]]+Table3[[#This Row],[Manufacturing lead time]] -> 21 | AE13: =Table3[[#This Row],[Shipping costs]]/Table3[[#This Row],[Number of products sold]] -> 0.0077487622 | AF13: =IF(AND(Table3[[#This Row],[Total Lead Time]]>Calculations!$B$6, Table3[[#This Row],[Defect rates]]>Calculations!$B$7), "Underperforming", IF(Table3[[#This Row],[Total Lead Time]]>Calculations!$B$6, "Slow", IF(Table3[[#This Row],[Defect rates]]>Calculations!$B$7, "Quality Issue", "Good"))) -> Good
... A101: Haircare | B101: SKU21 | C101: 84.893869 | D101: 60 | E101: 601 | F101: 7087.0527 | G101: Unknown | H101: 69 | I101: 25 | J101: 7 | K101: 6 | L101: Carrier B | M101: 6.0378838 | N101: Supplier 5 | O101: Chennai | P101: 19 | Q101: 791 | R101: 4 | S101: 61.735729 | T101: Pending | U101: 0.00018607568 | V101: Air | W101: Route C | X101: 523.36091 | Y101: =F101 -X101 -> 6563.6918 | Z101: =(Table3[[#This Row],[Revenue generated]]-Table3[[#This Row],[Costs]])/Table3[[#This Row],[Revenue generated]] -> 0.92615253 | AA101: =IF(Table3[[#This Row],[Stock levels]]<Table3[[#This Row],[Order quantities]]*0.2,"Critical",IF(Table3[[#This Row],[Stock levels]]<Table3[[#This Row],[Order quantities]]*0.5,"low","Adquate")) -> Adquate | AB101: =IF( F101 >=Calculations!$B$3,"High", IF(F101 >=Calculations!$B$2,"Medium", "Low")) -> Medium | AC101: =_xlfn.IFS(Table3[[#This Row],[Defect rates]] < 0.02,"Excellent",Table3[[#This Row],[Defect rates]] < 0.05,"Acceptable",Table3[[#This Row],[Defect rates]] < 0.1,"Concerning",Table3[[#This Row],[Defect rates]] > 0.1,"Critical") -> Excellent | AD101: =Table3[[#This Row],[order Lead times]]+Table3[[#This Row],[Manufacturing lead time]] -> 29 | AE101: =Table3[[#This Row],[Shipping costs]]/Table3[[#This Row],[Number of products sold]] -> 0.010046396 | AF101: =IF(AND(Table3[[#This Row],[Total Lead Time]]>Calculations!$B$6, Table3[[#This Row],[Defect rates]]>Calculations!$B$7), "Underperforming", IF(Table3[[#This Row],[Total Lead Time]]>Calculations!$B$6, "Slow", IF(Table3[[#This Row],[Defect rates]]>Calculations!$B$7, "Quality Issue", "Good"))) -> Good

Sheet Analysis sheet
A1: PIVOTE TABLES
A4: PT1 — Revenue & Sales by Product Type | C4: Product Type | D4: Units Sold | E4: Total Revenue | F4: Total Profit | G4: profit margin %
C5: Skincare | D5: 17798 | E5: 232435.27 | F5: 212918.03 | G5: 0.88676109
C6: Haircare | D6: 16539 | E6: 190341.78 | F6: 170795.74 | G6: 0.85426446
C7: Cosmetics | D7: 11762 | E7: 154827.77 | F7: 140966.47 | G7: 0.88187009
C8: Grand Total | D8: 46099 | E8: 577604.82 | F8: 524680.24 | G8: 0.87444058
A13: PT2 —Supplier Performance Analysis | C13: supplier name | D13: Lead days (Avg) | E13: Manufacturing costs (Avg) | F13: Defect rates % | G13: Total Revenue
C14: Supplier 4 | D14: 32.333333 | E14: 62.709727 | F14: 0.023373974 | G14: 86468.962
C15: Supplier 2 | D15: 31.818182 | E15: 41.622514 | F15: 0.023627501 | G15: 125467.42
C16: Supplier 5 | D16: 31.055556 | E16: 44.768243 | F16: 0.026654083 | G16: 110343.46
C17: Supplier 1 | D17: 29.37037 | E17: 45.254027 | F17: 0.018036297 | G17: 157529
C18: Supplier 3 | D18: 29.266667 | E18: 43.634121 | F18: 0.02465786 | G18: 97795.98
C19: Grand Total | D19: 30.73 | E19: 47.266693 | F19: 0.02277158 | G19: 577604.82
C22: Supplier Flag Summary
C23: Product count | D23: Column Labels
C24: supplier name | D24: Good | E24: Slow | F24: Grand Total
C25: Supplier 1 | D25: 22 | E25: 5 | F25: 27
C26: Supplier 2 | D26: 15 | E26: 7 | F26: 22
C27: Supplier 3 | D27: 13 | E27: 2 | F27: 15
C28: Supplier 4 | D28: 13 | E28: 5 | F28: 18
C29: Supplier 5 | D29: 12 | E29: 6 | F29: 18
C30: Grand Total | D30: 75 | E30: 25 | F30: 100
A36: PT3 —Inventory & Stock Risk Analysis | C36: no of product | D36: Column Labels
C37: product type | D37: Adquate | E37: Critical | F37: low | G37: Grand Total
C38: Cosmetics | D38: 18 | E38: 4 | F38: 4 | G38: 26
C39: Haircare | D39: 24 | E39: 5 | F39: 5 | G39: 34
C40: Skincare | D40: 28 | E40: 7 | F40: 5 | G40: 40
C41: Grand Total | D41: 70 | E41: 16 | F41: 14 | G41: 100
C43: Stock Details for Critical Items only
C44: Stock Risk | D44: (All)
C46: product type | D46: Total Stock levels | E46: Order quantities (Avg)
C47: Cosmetics | D47: 1201 | E47: 50.730769
C48: Haircare | D48: 1590 | E48: 49.147059
C49: Skincare | D49: 1986 | E49: 48.3
C50: Grand Total | D50: 4777 | E50: 49.22
A54: PT4 — Shipping & Logistics Analysis
A55: PT4a — Carrier Cost Comparison: | C55: carrier name | D55: Shipping costs (Avg) | E55: Shipping Cost Per Unit (Avg) | F55: Shipping times (avg) | G55: Total Revenue shipped
C56: Carrier A | D56: 5.5549225 | E56: 0.019707198 | F56: 6.1428571 | G56: 142629.99
C57: Carrier B | D57: 5.509247 | E57: 0.046356587 | F57: 5.3023256 | G57: 250094.65
C58: Carrier C | D58: 5.5992916 | E58: 0.042386486 | F58: 6.0344828 | G58: 184880.18
...

Sheet Calculations
A1: Metric | B1: Value
A2: Revenue 33rd Percentile | B2: =PERCENTILE(clean_data!F2:F101,0.33) -> 4189.5596
A3: Revenue 66th Percentile | B3: =PERCENTILE(clean_data!F2:F101,0.66) -> 7721.6847
A6: High Lead Time Threshold: | B6: 39
A7: High Defect Threshold: | B7: 0.05
A10: verage Total Lead Time value | B10: =AVERAGE(Table3[[#All],[Total Lead Time]]) -> 30.73
A12: Toal Revenue | B12: =SUM(clean_data!F2:F101) -> 577604.82
A13: Total Cost | B13: =SUM(Table3[Costs]) -> 52924.578
A14: Overall Profit Margin | B14: =(SUM(Table3[Revenue generated])-SUM(Table3[Costs]))/SUM(Table3[Revenue generated]) -> 0.90837234
A15: Avg Defect Rate | B15: =AVERAGE(Table3[Defect rates]) -> 0.02277158
A16: Avg Total Lead Time | B16: =AVERAGE(Table3[Total Lead Time]) -> 30.73
A17: Avg Shipping Cost/Unit | B17: =AVERAGE(Table3[Shipping costs]) -> 5.5481491
A18: Critical Stock Items | B18: =COUNTIF(Table3[Stock Risk],"Critical") -> 16
A20: Supplier 4 Avg Lead Time (Highest) | B20: 32.33
A21: Supplier 1 Avg Defect Rate % (Lowest) | B21: 0.018
A22: Carrier A Cost Per Unit (Lowest) | B22: 0.0197
A23: Carrier B Cost Per Unit (Highest) | B23: 0.0464

Sheet analysis_sheet_2
A1: PIVOT TABLES FOR PIVOT CHART
A4: Revenue Contribution by Product Type | D4: Inventory Risk Distribution | G4: Revenue and Profit Margin by Product Type
A5: Product Type | B5: Total Revenue | D5: Row Labels | E5: Total Stock | G5: Product Type | H5: Total Revenue | I5: profit margin %
A6: Skincare | B6: 232435.27 | D6: Adquate | E6: 70 | G6: Skincare | H6: 232435.27 | I6: 0.88676109
A7: Haircare | B7: 190341.78 | D7: Critical | E7: 16 | G7: Haircare | H7: 190341.78 | I7: 0.85426446
A8: Cosmetics | B8: 154827.77 | D8: low | E8: 14 | G8: Cosmetics | H8: 154827.77 | I8: 0.88187009
A9: Grand Total | B9: 577604.82 | D9: Grand Total | E9: 100 | G9: Grand Total | H9: 577604.82 | I9: 0.87444058
B13: Supplier Lead Time Comparison | E13: Shipping Cost Efficiency by Carrier | H13: Revenue by city
B14: supplier name | C14: Lead days (Avg) | E14: Row Labels | F14: Lead days (Avg) | H14: Row Labels | I14: Sum of Revenue generated
B15: Supplier 4 | C15: 32.333333 | E15: Supplier 3 | F15: 29.266667 | H15: Mumbai | I15: 137755.03
B16: Supplier 2 | C16: 31.818182 | E16: Supplier 1 | F16: 29.37037 | H16: Kolkata | I16: 137077.55
B17: Supplier 5 | C17: 31.055556 | E17: Supplier 5 | F17: 31.055556 | H17: Chennai | I17: 119142.82
B18: Supplier 1 | C18: 29.37037 | E18: Supplier 2 | F18: 31.818182 | H18: Bangalore | I18: 102601.72
B19: Supplier 3 | C19: 29.266667 | E19: Supplier 4 | F19: 32.333333 | H19: Delhi | I19: 81027.701
B20: Grand Total | C20: 30.73 | E20: Grand Total | F20: 30.73 | H20: Grand Total | I20: 577604.82
G46: carrier name | H46: Shipping Cost Per Unit (Avg)
G47: Carrier A | H47: 0.019707198
G48: Carrier B | H48: 0.046356587
G49: Carrier C | H49: 0.042386486
G50: Grand Total | H50: 0.037743429

Sheet dashboard
A1: GlowChain Beauty Co. — Supply Chain Performance Dashboard
AA11: *Interactive executive dashboard for monitoring revenue, inventory risk, supplier performance, logistics efficiency, and product quality.*
